Workbook

Sheet 0. 안내
A1: 쿠팡·네이버 경쟁사 다채널 수집 템플릿
A2: 수집일 기준 | B2: 2026.04.__ (수집 시 기입)
A3: 작업 소요 예상 | B3: 카테고리당 7-10분 × 11개 = 약 90-120분
A5: 작업 방법
A6: 1단계 | B6: '1. 수집 시트' 탭 열기 → 노란색 셀만 채우면 됨 (회색 셀은 참고용 기존값)
A7: 2단계 | B7: 쿠팡(www.coupang.com)에서 제품명 검색 → 상세페이지 진입
B8: → 쿠팡 리뷰수(G열), 쿠팡 판가(H열), 쿠팡 평점(I열), 로켓여부(J열) 기입
A9: 3단계 | B9: 네이버 쇼핑(shopping.naver.com)에서 제품명 검색 → 스마트스토어 상세
B10: → 네이버 판가(K열), 6개월 구매건수(L열 ★중요), 리뷰수(M열) 기입
B11: ※ 6개월 구매건수: 스스뷰어 크롬 확장(무료) 설치 → 상품페이지에서 확장 아이콘 클릭
A12: 4단계 | B12: 이마트몰(emart.ssg.com) 검색 → 판매여부(N열), 판가(O열) 기입
A13: 5단계 | B13: 수집 끝나면 저장 후 저에게 '수집 완료' 메시지로 이 파일 첨부
B14: → 제가 받은 데이터로 TUBBLE 시장맵 v5.5 자동 업데이트합니다
A16: 중요 규칙
A17: ✓ Must Do | B17: 모든 수치는 수집일 당일 기준 화면 그대로 기입 (계수·환산·추정 금지)
B18: 수집 불가한 항목은 'N/A' + 사유 (예: 'N/A 품절', 'N/A 스스뷰어 미노출')
B19: 동일 브랜드 여러 SKU 시 리뷰수 최다 SKU 1개만 선정
B20: 광고·쿠팡 파트너스 배너는 정규 랭킹으로 혼동 금지
A21: ✗ Must Not | B21: 본 기억·느낌으로 수치 추측 입력 금지
B22: 네이버 일반 리뷰수와 스마트스토어 6개월 구매건수 혼동 금지
A24: 색상 가이드
A25: 노랑(필수) | B25: 반드시 채워야 하는 셀 — 새로 수집한 쿠팡/네이버/이마트 데이터
A26: 회색(참고) | B26: v5.2 기존 추정값 — 비교 참고용, 수정 불필요
A27: 파랑헤더 | B27: 컬럼 구분용 헤더
A29: 수집 팁
A30: 쿠팡 리뷰수 | B30: 상품 상세페이지 상단 별점 옆 괄호 안 숫자 (예: '★ 4.8 (8,224)')
A31: 쿠팡 평점 | B31: 소수점 1자리 (예: 4.8)
A32: 쿠팡 로켓여부 | B32: '로켓배송' / '로켓프레시' / '로켓직구' / '일반' 중 선택
A33: 네이버 6개월 구매건수 | B33: 스스뷰어 팝업의 '최근 6개월 판매건수' 숫자만 기입 (쉼표 제외 숫자만)
B34: 스스뷰어 설치: Chrome 웹스토어 '스마트스토어 판매건수 뷰어' 검색 → '추가'
A35: 이마트 판매여부 | B35: 'O' (판매 중) / 'X' (미판매/품절)

Sheet 1. 수집
A1: 카테고리 | B1: 순위 | C1: 제품명 | D1: 브랜드 | E1: 용량/스펙 | F1: 기존 가격(참고) | G1: 쿠팡 리뷰수 ★ | H1: 쿠팡 판가(원) ★ | I1: 쿠팡 평점 ★ | J1: 로켓여부 ★ | K1: 쿠팡 최근 한달 판매건 수 추정 수치 | L1: 네이버 판가(원) | M1: 네이버 6개월 구매건수 ★ | N1: 네이버 리뷰수 | O1: 이마트 판매여부 | P1: 이마트 판가(원) | Q1: 특이사항 (품절·프로모션 등) | R1: 수집일
A2: A1 세탁세제 (실내건조 중심) | B2: 1 | C2: 허글리 8IN1 딥클린 초고농축 캡슐세탁세제 코튼캔디 향 1개, 100개입 | D2: 허글리 | E2: 8g x 100캡슐 | F2: 15800 | G2: 14022 | H2: 14800 | I2: 5 | J2: 판매자로켓 | K2: 30000
A3: A1 세탁세제 (실내건조 중심) | B3: 2 | C3: 퍼실 뉴 디스크 프로 플러스 캡슐세제, 40개입 1개 | D3: 퍼실 | E3: 25g x 40캡슐 | F3: 19600 | G3: 5432 | H3: 16460 | I3: 5 | J3: 로켓배송 | K3: 20000
A4: A1 세탁세제 (실내건조 중심) | B4: 3 | C4: 맘스럽 퍼펙트 캡슐세제 4챔버 파우치형 국산제조 8배 초고농축 4in1 대용량 실내건조, 100개입 | D4: 맘스럽 | E4: 16g x 100캡슐 | F4: 11250 | G4: 6456 | H4: 8720 | I4: 5 | J4: 일반배송 | K4: 10000
A5: A1 세탁세제 (실내건조 중심) | B5: 4 | C5: 부케가르니 딥클린 초고농축 캡슐세제 100개입 1개 | D5: 부케가르니 | E5: 8g x 100캡슐 | F5: 11900 | G5: 25038 | H5: 11900 | I5: 4.5 | J5: 로켓배송 | K5: 10000
A6: A1 세탁세제 (실내건조 중심) | B6: 5 | C6: 스너글 블루스파클 플러스 실내건조 캡슐세제 27개입 | D6: 스너글 | E6: 15.2g x 27캡슐 | F6: 13500 | G6: 7715 | H6: 13000 | I6: 5 | J6: 로켓배송 | K6: 7000
A7: A1 세탁세제 (실내건조 중심) | B7: 6 | C7: 액츠 멀티 솔루션 실내건조 컴팩트 캡슐세제 50개입 1개 | D7: 액츠 | E7: 7g x 50캡슐 | F7: 13900 | G7: 5336 | H7: 11950 | I7: 5 | J7: 로켓배송 | K7: 7000
A8: A1 세탁세제 (실내건조 중심) | B8: 7 | C8: 카포드 센트라린 듀얼코어 캡슐세제 35개입 | D8: 카포드 | E8: 16g x 42캡슐 | F8: 19770 | G8: 5989 | H8: 19770 | I8: 5 | J8: 로켓배송 | K8: 6000
A9: A1 세탁세제 (실내건조 중심) | B9: 8 | C9: 쉬슬러 울트라 액티브 초고농축 캡슐세제 릴라향 100개입 1개 | D9: 쉬슬러 | E9: 8g x 100캡슐 | F9: 11000 | G9: 4735 | H9: 9900 | I9: 5 | J9: 로켓배송 | K9: 5000
A10: A1 세탁세제 (실내건조 중심) | B10: 9 | C10: 테크 딥클린 초고농축 캡슐세제 80개입 1개 | D10: 테크 | E10: 8g x 80캡슐 | F10: 10900 | G10: 2397 | H10: 9910 | I10: 5 | J10: 로켓배송 | K10: 3000
A11: A1 세탁세제 (실내건조 중심) | B11: 10 | C11: 비트 실내건조 캡슐세제 그린플로럴향 42개입 | D11: 비트 | E11: 16g x 42캡슐 | F11: 16900 | G11: 11554 | H11: 16050 | I11: 5 | J11: 로켓배송 | K11: 3000
A13: A4 얼룩제거제 | B13: 1 | C13: 마이비 얼룩제거제 330ml 1개 | D13: 마이비 | E13: 330ml | F13: 7900 | G13: 23918 | H13: 7900 | I13: 5 | J13: 로켓배송 | K13: 10000
A14: A4 얼룩제거제 | B14: 2 | C14: 테크 바르는 섬유 얼룩제거제 220ml | D14: 테크 | E14: 220ml | F14: 3670 | G14: 3315 | H14: 3480 | I14: 5 | J14: 로켓배송 | K14: 8000
... A50: A7 드라이시트/건조기시트 | B50: 5 | C50: 라비킷 코트너 건조기 시트 섬유유연제 비누향 본품 40개입 1개 | D50: 라비킷 | E50: 40매 | F50: 18500 | G50: 11468 | H50: 18500 | I50: 5 | J50: 로켓배송 | K50: 7000
A51: A7 드라이시트/건조기시트 | B51: 6 | C51: 커클랜드시그니처 드라이시트 시트형 섬유유연제 본품 1개 | E51: 250매 | F51: 10350 | G51: 7025 | H51: 10350 | I51: 4.5 | J51: 판매자로켓 | K51: 4000
A52: A7 드라이시트/건조기시트 | B52: 7 | C52: 라버비 독일더마 비건인증 초고농축 건조기용 드라이시트 허그코튼 3개 120개입 | D52: 라버비 | E52: 120매 X 3개 | F52: 29800 | G52: 682 | H52: 29800 | I52: 5 | J52: 로켓배송 | K52: 3000
A53: A7 드라이시트/건조기시트 | B53: 8 | C53: 다우니 드라이시트 에이프릴 본품 240매 | D53: 다우리 | E53: 240매 | F53: 20030 | G53: 24894 | H53: 20030 | I53: 4.5 | J53: 일반배송 | K53: 2000
A54: A7 드라이시트/건조기시트 | B54: 9 | C54: 부케가르니 딥 퍼퓸 드라이시트 섬유유연제 화이트머스크 본품 120매 | D54: 부케가르니 | E54: 120매 | F54: 9900 | G54: 6483 | H54: 9900 | I54: 4.5 | J54: 로켓배송 | K54: 2000
A55: A7 드라이시트/건조기시트 | B55: 10 | C55: 일비아 일반용 건조기 퍼퓸 시트 섬유유연제 코튼 블루 본품 40개입 1개 | D55: 일비아 | E55: 40 | F55: 12790 | G55: 6274 | H55: 12790 | I55: 5 | J55: 로켓배송 | K55: 1000
A57: B1 주방세제 | B57: 1 | C57: 퐁퐁 오렌지 오일 담은 친환경 주방세제 기분 좋은 오렌지향 리필 1.2L 2개 | D57: 퐁퐁 | E57: 1.2L X 2개 | F57: 4800 | G57: 35847 | H57: 4700 | I57: 5 | J57: 로켓배송 | K57: 30000
A58: B1 주방세제 | B58: 2 | C58: 프릴 시크릿오브 베이킹소다 퓨어레몬향 리필 1L 2개 | D58: 프릴 | E58: 1L X 2개 | F58: 8480 | G58: 145248 | H58: 8480 | I58: 5 | J58: 로켓배송 | K58: 40000
A59: B1 주방세제 | B59: 3 | C59: 탐사 베이킹소다 주방세제 레몬향 780ml 2개 | D59: 탐사 | E59: 780ml X 2개 | F59: 5000 | G59: 122771 | H59: 5000 | I59: 5 | J59: 로켓배송 | K59: 30000
A60: B1 주방세제 | B60: 4 | C60: 참그린 레몬 녹차 뽀드득 어드밴스 주방세제 리필 1.2L 3개 | D60: 참그린 | E60: 1.2L X 3개 | F60: 8400 | G60: 78155 | H60: 8400 | I60: 5 | J60: 로켓배송 | K60: 10000
A61: B1 주방세제 | B61: 5 | C61: 순샘 구연산 자몽향 주방세제 리필 1.6L 2개 | D61: 순샘 | E61: 1.6L X 2개 | F61: 7420 | G61: 81363 | H61: 7320 | I61: 5 | J61: 로켓배송 | K61: 9000
A62: B1 주방세제 | B62: 6 | C62: 피죤퓨어 뽀드득 주방세제 자몽향 1개 1.2L | D62: 피죤 | E62: 1.2L | F62: 2280 | G62: 3573 | H62: 2280 | I62: 5 | J62: 로켓배송 | K62: 2000
A63: B1 주방세제 | B63: 7 | C63: 비앤비 액상형 젖병세정제 허브그린향 600ML | D63: 비앤비 | E63: 600ml | F63: 4750 | G63: 23551 | H63: 4750 | I63: 4.5 | J63: 로켓배송 | K63: 7000
A64: B1 주방세제 | B64: 8 | C64: 프랭클린 주방세제&젖병세정제 500ml | D64: 프랭클린 | E64: 500ml | F64: 7920 | G64: 1726 | H64: 7920 | I64: 5 | J64: 로켓배송 | K64: 5000
A65: B1 주방세제 | B65: 9 | C65: 자연퐁 찌든때 걱정 없는 솔잎 파워워시 주방 세제 용기형 980ml 2개 | D65: 자연퐁 | E65: 980ml X 2개 | F65: 9100 | G65: 3283 | H65: 8190 | I65: 5 | J65: 로켓배송 | K65: 4000
A66: B1 주방세제 | B66: 10 | C66: 부케가르니 에코 주방세제 레몬향 리필 2.1L | D66: 부케가르니 | E66: 2.1L | F66: 5900 | G66: 6180 | H66: 5900 | I66: 4.5 | J66: 로켓배송 | K66: 3000
A68: B2 식기세척기세제 | B68: 1 | C68: 자연퐁 스팀워시 식기세척기용 세제 베이킹소다 55입 550G | D68: 자연퐁 | E68: 550g | F68: 11800 | G68: 17905 | H68: 11210 | I68: 5 | J68: 로켓배송 | K68: 10000
A69: B2 식기세척기세제 | B69: 2 | C69: 프로쉬 올인원 베이킹소다 식기세척기 세제 30p, 540g | D69: 프로쉬 | E69: 540g | F69: 9800 | G69: 8167 | H69: 9800 | I69: 5 | J69: 로켓배송 | K69: 8000
... A95: C2 변기세정제 | B95: 6 | C95: 브레프 파워액티브 변기세정제 라벤더향 50g 10개 | D95: 브레프 | E95: 10개 | F95: 14820 | G95: 44693 | H95: 14820 | I95: 4.5 | J95: 로켓배송 | K95: 3000
A96: C2 변기세정제 | B96: 7
A97: C2 변기세정제 | B97: 8
A98: C2 변기세정제 | B98: 9
A99: C2 변기세정제 | B99: 10
A101: D1 다목적 세정제 | B101: 1 | C101: 브리오신 사봉 느와르 다목적 세정제 750ml | D101: 브리오신 | E101: 750ml | F101: 17580 | G101: 9379 | H101: 17050 | I101: 4.5 | J101: 로켓배송 | K101: 1000
A102: D1 다목적 세정제 | B102: 2 | C102: 부케가르니 퍼펙트 클리어 다목적 세정제 750ml | D102: 부케가르니 | E102: 750ml | F102: 5900 | G102: 1933 | H102: 5900 | I102: 4.5 | J102: 로켓배송 | K102: 2000
A103: D1 다목적 세정제 | B103: 3 | C103: 생활공식 초강력 다목적 클리너 500ml 2개 | D103: 생활공식 | E103: 500ml X 2개 | F103: 19800 | G103: 17435 | H103: 19800 | I103: 4.5 | J103: 로켓배송 | K103: 1000
A104: D1 다목적 세정제 | B104: 4 | C104: 청소해결사 크린피비 찌든때 기름때 제거 650ml 2개 | D104: 청소해결사 | E104: 650ml X 2개 | F104: 6130 | G104: 1294 | H104: 6130 | I104: 4.5 | J104: 로켓배송 | K104: 1000
...

Sheet 2. 카테고리 요약
A1: 카테고리별 수집 진행 현황 (자동 집계)
A3: 카테고리 | B3: 제품 수 | C3: 쿠팡 리뷰 수집 완료 | D3: 네이버 구매건수 수집 완료 | E3: 수집률(%) | F3: 주의
A4: A1 세탁세제 (실내건조 중심) | B4: =COUNTA('1. 수집'!C2:C11) -> 10 | C4: =COUNT('1. 수집'!G2:G11) -> 10 | D4: =COUNT('1. 수집'!M2:M11) -> 0 | E4: =IFERROR((C4+D4)/(B4*2),0) -> 0.5
A5: A4 얼룩제거제 | B5: =COUNTA('1. 수집'!C13:C22) -> 10 | C5: =COUNT('1. 수집'!G13:G22) -> 10 | D5: =COUNT('1. 수집'!M13:M22) -> 0 | E5: =IFERROR((C5+D5)/(B5*2),0) -> 0.5
A6: A5 세탁조클리너 | B6: =COUNTA('1. 수집'!C24:C33) -> 10 | C6: =COUNT('1. 수집'!G24:G33) -> 10 | D6: =COUNT('1. 수집'!M24:M33) -> 0 | E6: =IFERROR((C6+D6)/(B6*2),0) -> 0.5
A7: A6 이염방지 시트 | B7: =COUNTA('1. 수집'!C35:C44) -> 10 | C7: =COUNT('1. 수집'!G35:G44) -> 10 | D7: =COUNT('1. 수집'!M35:M44) -> 0 | E7: =IFERROR((C7+D7)/(B7*2),0) -> 0.5
A8: A7 드라이시트/건조기시트 | B8: =COUNTA('1. 수집'!C46:C55) -> 10 | C8: =COUNT('1. 수집'!G46:G55) -> 10 | D8: =COUNT('1. 수집'!M46:M55) -> 0 | E8: =IFERROR((C8+D8)/(B8*2),0) -> 0.5
A9: B1 주방세제 | B9: =COUNTA('1. 수집'!C57:C66) -> 10 | C9: =COUNT('1. 수집'!G57:G66) -> 10 | D9: =COUNT('1. 수집'!M57:M66) -> 0 | E9: =IFERROR((C9+D9)/(B9*2),0) -> 0.5
A10: B2 식기세척기세제 | B10: =COUNTA('1. 수집'!C68:C77) -> 10 | C10: =COUNT('1. 수집'!G68:G77) -> 10 | D10: =COUNT('1. 수집'!M68:M77) -> 0 | E10: =IFERROR((C10+D10)/(B10*2),0) -> 0.5
A11: B3 용기세척제 (텀블러) | B11: =COUNTA('1. 수집'!C79:C88) -> 10 | C11: =COUNT('1. 수집'!G79:G88) -> 10 | D11: =COUNT('1. 수집'!M79:M88) -> 0 | E11: =IFERROR((C11+D11)/(B11*2),0) -> 0.5
A12: C2 변기세정제 | B12: =COUNTA('1. 수집'!C90:C99) -> 6 | C12: =COUNT('1. 수집'!G90:G99) -> 6 | D12: =COUNT('1. 수집'!M90:M99) -> 0 | E12: =IFERROR((C12+D12)/(B12*2),0) -> 0.5
A13: D1 다목적 세정제 | B13: =COUNTA('1. 수집'!C101:C110) -> 7 | C13: =COUNT('1. 수집'!G101:G110) -> 7 | D13: =COUNT('1. 수집'!M101:M110) -> 0 | E13: =IFERROR((C13+D13)/(B13*2),0) -> 0.5
A14: D6 탈취제 (공간 겔) | B14: =COUNTA('1. 수집'!C112:C121) -> 10 | C14: =COUNT('1. 수집'!G112:G121) -> 10 | D14: =COUNT('1. 수집'!M112:M121) -> 0 | E14: =IFERROR((C14+D14)/(B14*2),0) -> 0.5
A15: 전체 합계 | B15: =SUM(B4:B14) -> 103 | C15: =SUM(C4:C14) -> 103 | D15: =SUM(D4:D14) -> 0 | E15: =IFERROR((C15+D15)/(B15*2),0) -> 0.5
A17: 수집률 100% 달성 시 저에게 파일 전달해주세요 → v5.5 자동 업데이트

Sheet 1. 수집 - 쿠팡(병권)
A1: 카테고리 | B1: 순위 | C1: 제품명 | D1: 브랜드 | E1: 용량/스펙 | F1: 기존 가격(참고) | G1: 쿠팡 리뷰수 ★ | H1: 쿠팡 판가(원) ★ | I1: 쿠팡 평점 ★ | J1: 로켓여부 ★ | K1: 쿠팡 최근 한달 판매건 수 추정 수치 | L1: 네이버 판가(원) | M1: 네이버 6개월 구매건수 ★ | N1: 네이버 리뷰수 | O1: 이마트 판매여부 | P1: 이마트 판가(원) | Q1: 특이사항 (품절·프로모션 등) | R1: 수집일
A2: 액체세제 | B2: 1 | C2: 퍼실 딥클린 라벤더젤 플러스 드럼용 액상세제 라벤더 코튼향 리필 | D2: 퍼실 | E2: 1.5L x 2 | F2: 31000 | G2: 71942 | H2: 11340 | I2: 5 | J2: 로켓배송 | K2: 30000
A3: 액체세제 | B3: 2 | C3: 액츠 퍼펙트 실내건조 일반용 프레시 플로럴향 액상세제 본품 | D3: 액츠 | E3: 3.2L x 1 | F3: 14900 | G3: 98978 | H3: 9970 | I3: 5 | J3: 로켓배송 | K3: 20000
A4: 액체세제 | B4: 3 | C4: 탐사 파워워시 액체세제 본품 | D4: 탐사 | E4: 2.5L x 4 | F4: 14900 | G4: 235704 | H4: 10990 | I4: 5 | J4: 로켓배송 | K4: 10000
A5: 액체세제 | B5: 4 | C5: 퍼실 라벤더젤 플러스 드럼용 액상세제 본품 | D5: 퍼실 | E5: 2.7L x 1 | F5: 29900 | G5: 33912 | H5: 11550 | I5: 5 | J5: 로켓배송 | K5: 10000
A6: 액체세제 | B6: 5 | C6: 세제 리퀴드 라벤더향 세탁세제 실내건조 중성 액체세제 | D6: 리퀴드 | E6: 2.5L x 4 | F6: 12000 | G6: 2145 | H6: 7410 | I6: 4.5 | J6: 판매자로켓 | K6: 7000
A7: 액체세제 | B7: 6 | C7: 다우니 실내건조 초고농축 섬유유연제 프레시 클린 자스민향 리필 | D7: 다우니 | E7: 1.35L x 1 | F7: 10900 | G7: 33300 | H7: 8030 | I7: 5 | J7: 로켓배송 | K7: 7000
A8: 액체세제 | B8: 7 | C8: 다우니 탈취 실내건조 자스민향 세탁세제 본품 | D8: 다우니 | E8: 3L x 1 | F8: 32400 | G8: 79273 | H8: 19690 | I8: 5 | J8: 로켓배송
A9: 액체세제 | B9: 8 | C9: 리큐 진한겔 하이브리드 플로랄향 일반용 액상세제 리필 | D9: 리큐 | E9: 2.1L x 4 | F9: 31500 | G9: 103928 | H9: 18900 | I9: 5 | J9: 로켓배송
A10: 액체세제 | B10: 9 | C10: 퍼실 라벤더 젤 플러스 일반용 코튼향 액상세제 본품 | D10: 퍼실 | E10: 2.7L x 1 | F10: 29900 | G10: 16296 | H10: 11710 | I10: 5 | J10: 로켓배송 | K10: 5000
A11: 액체세제 | B11: 10 | C11: 다우니 탈취 실내건조 세탁세제 리필 | D11: 다우니 | E11: 4.1L x 1 | F11: 38920 | G11: 52443 | H11: 24290 | I11: 5 | J11: 로켓배송 | K11: 3000
A13: 분말세제 | B13: 1 | C13: 슈퍼워시 가루세제 본품 | D13: 슈퍼워시 | E13: 10kg x 1 | F13: 14800 | G13: 28837 | H13: 8930 | I13: 4.5 | J13: 판매자로켓 | K13: 10000
A14: 분말세제 | B14: 2 | C14: 스파크 스마트 클린 분말세제 리필 | D14: 스파크 | E14: 9.5Kg x 2 | F14: 38100 | G14: 74949 | H14: 23340 | I14: 5 | J14: 로켓배송 | K14: 8000
A15: 분말세제 | B15: 3 | C15: 탐사 찬물에서도 강한 파워워시 일반드럼 겸용 분말 세제 리필 | D15: 탐사 | E15: 10kg x 1 | F15: 7990 | G15: 30701 | H15: 7990 | I15: 5 | J15: 로켓배송 | K15: 8000
A16: 분말세제 | B16: 4 | C16: 수퍼타이 찬물전용 베이킹소다 PLUS 가루세제 | D16: 수퍼타이 | E16: 5kg x 1 | F16: 13900 | G16: 16505 | H16: 8780 | I16: 4.5 | J16: 로켓배송 | K16: 4000
A17: 분말세제 | B17: 5 | C17: 소다스쿨 워싱소다 세탁세제 | D17: 소다스쿨 | E17: 3kg x 1 | F17: 12000 | G17: 22397 | H17: 8280 | I17: 5 | J17: 로켓배송 | K17: 4000
A18: 분말세제 | B18: 6 | C18: 스파크 시그니처 분말세제 바스켓 본품 | D18: 스파크 | E18: 6kg x 1 | F18: 31500 | G18: 1390 | H18: 14900 | I18: 5 | J18: 로켓배송 | K18: 3000
A19: 분말세제 | B19: 7 | C19: 비트 분말세제 일반용 리필 | D19: 비트 | E19: 3.2kg x 1 | F19: 7180 | G19: 64535 | H19: 7180 | I19: 5 | J19: 로켓배송 | K19: 2000
A20: 분말세제 | B20: 8 | C20: 순수크린 베이킹소다 파우치 1등급원료사용 천연세탁세제 대용량 다목적 주방세제 | D20: 순수크린 | E20: 5kg x 1 | F20: 8300 | G20: 14304 | H20: 7800 | I20: 5 | J20: 로켓배송
A21: 분말세제 | B21: 9 | C21: 맘스럽 워싱소다 버킷100% 프리미엄 세탁세제 초강력 세탁보조제 | D21: 맘스럽 | E21: 5kg x 1 | F21: 13490 | G21: 2507 | H21: 9890 | I21: 5 | J21: - | K21: 2000
A22: 분말세제 | B22: 10 | C22: 넬리 100회 쓰는 소다 분말세제 리필 | D22: 넬리 | E22: 1.5kg x 1 | F22: 22400 | G22: 9022 | H22: 22400 | I22: 5 | J22: 로켓배송
A24: 섬유유연제 | B24: 1 | C24: 스너글 초고농축 섬유유연제 오리지널 허거블 코튼 본품 | D24: 스너글 | E24: 4L x 1 | F24: 24900 | G24: 144149 | H24: 15640 | I24: 5 | J24: 로켓배송 | K24: 20000
A25: 섬유유연제 | B25: 2 | C25: 2020 다우니 엑스퍼트 실내건조 초고농축 섬유유연제 본품 | D25: 다우니 | E25: 1L x 1 | F25: 8900 | G25: 2997 | H25: 8900 | I25: 5 | J25: 로켓배송 | K25: 6000
A26: 섬유유연제 | B26: 3 | C26: 다우니 초고농축 호텔 컬렉션 섬유유연제 미스티크 본품 | D26: 다우니 | E26: 1kg x 1 | F26: 9500 | G26: 155121 | H26: 6820 | I26: 5 | J26: 로켓배송 | K26: 5000
A27: 섬유유연제 | B27: 4 | C27: 스너글 초고농축 섬유유연제 오리지널 허거블 코튼 리필 | D27: 스너글 | E27: 2.6L x 1 | F27: 23400 | G27: 30808 | H27: 11320 | I27: 5 | J27: 로켓배송 | K27: 5000
A28: 섬유유연제 | B28: 5 | C28: 다우니 엑스퍼트 실내건조 초고농축 섬유유연제 프레시 클린 본품 | D28: 다우니 | E28: 1.05L x 1 | F28: 21950 | G28: 2997 | H28: 21950 | I28: 5 | J28: 로켓배송 | K28: 3000
A29: 섬유유연제 | B29: 6 | C29: 피죤 레귤러 섬유유연제 핑크로즈 본품 | D29: 피죤 | E29: 3L x 1 | F29: 8200 | G29: 276870 | H29: 4260 | I29: 5 | J29: 로켓배송 | K29: 3000
A30: 섬유유연제 | B30: 7 | C30: 피죤 레귤러 섬유유연제 핑크로즈 리필 | D30: 피죤 | E30: 2.1L x 3 | F30: 15300 | G30: 117981 | H30: 8100 | I30: 5 | J30: 로켓배송 | K30: 2000
A31: 섬유유연제 | B31: 8 | C31: 스너글 실내건조 섬유유연제 허거블 선샤인 본품 | D31: 스너글 | E31: 2L x 1 | F31: 18900 | G31: 10280 | H31: 10410 | I31: 5 | J31: 로켓배송 | K31: 2000
A32: 섬유유연제 | B32: 9 | C32: 다우니 업그레이드 섬유유연제 로맨스 본품 | D32: 다우니 | E32: 8.5L x 1 | F32: 34900 | G32: 40275 | H32: 31900 | I32: 5 | J32: 로켓배송 | K32: 1000
A33: 섬유유연제 | B33: 10 | C33: 다우니 실내건조 섬유유연제 플로럴블로썸 본품 | D33: 다우니 | E33: 1L x 1 | F33: 9500 | G33: 33816 | H33: 6620 | I33: 5 | J33: 로켓배송 | K33: 1000
A35: 울세제 | B35: 1 | C35: 테크 울드라이 오리지널 중성세제 본품 | D35: 테크 | E35: 1.5L x 1 | F35: 8900 | G35: 7767 | H35: 6460 | I35: 5 | J35: 로켓배송 | K35: 10000
A36: 울세제 | B36: 2 | C36: 울샴푸 다운워시 본품 | D36: 울샴푸 | E36: 800ml x 1 | F36: 14500 | G36: 14642 | H36: 9640 | I36: 5 | J36: 로켓배송 | K36: 3000
... A38: 울세제 | B38: 4 | C38: 울샴푸 오리지널 리필 | D38: 울샴푸 | E38: 1.5L x 1 | F38: 17600 | G38: 39639 | H38: 7990 | I38: 5 | J38: 로켓배송 | K38: 2000
A39: 울세제 | B39: 5 | C39: 테크 울드라이 오리지널 중성세제 리필 | D39: 테크 | E39: 1.3L x 1 | F39: 5900 | G39: 17199 | H39: 4750 | I39: 5 | J39: 로켓배송
A40: 울세제 | B40: 6 | C40: 부케가르니 젠틀 클리어 중성 울 세제 본품 | D40: 부케가르니 | E40: 3L x 1 | F40: 18000 | G40: 4109 | H40: 9900 | I40: 5 | J40: 로켓배송 | K40: 1000
A41: 울세제 | B41: 7 | C41: 탐사 울세제 중성세제 리필 | D41: 탐사 | E41: 1.5L x 1 | F41: 4100 | G41: 5650 | H41: 3260 | I41: 5 | J41: 로켓배송 | K41: 700
A42: 울세제 | B42: 8 | C42: 소키 간편한 속옷 울 중성세제 본품 | D42: 소키 | E42: 500ml x 2 | F42: 7840 | G42: 4933 | H42: 7840 | I42: 4.5 | J42: 로켓배송 | K42: 900
A43: 울세제 | B43: 9 | C43: 울터치 중성세제 리필 | D43: 울터치 | E43: 1.3L x 2 | F43: 25000 | G43: 21549 | H43: 7300 | I43: 5 | J43: 로켓배송 | K43: 1000
A44: 울세제 | B44: 10 | C44: 애경 울샴푸 중성세탁세제 대용량 | D44: 울샴푸 | E44: 4.5L x. | F44: 9790 | G44: 1820 | H44: 8650 | I44: 5 | J44: 로켓배송 | K44: 900
...
